import { render, screen } from '@testing-library/react';
import ErrorBoundary from '../ErrorBoundary';

// Component that throws an error for testing
const ThrowError = ({ shouldThrow }: { shouldThrow: boolean }) => {
  if (shouldThrow) {
    throw new Error('Test error');
  }
  return <div>No error</div>;
};

describe('ErrorBoundary', () => {
  // Mock console.error to avoid noise in test output
  const originalError = console.error;
  beforeAll(() => {
    console.error = vi.fn();
  });
  afterAll(() => {
    console.error = originalError;
  });

  it('renders children when there is no error', () => {
    render(
      <ErrorBoundary>
        <ThrowError shouldThrow={false} />
      </ErrorBoundary>
    );

    expect(screen.getByText('No error')).toBeInTheDocument();
  });

  it('renders error UI when there is an error', () => {
    render(
      <ErrorBoundary>
        <ThrowError shouldThrow={true} />
      </ErrorBoundary>
    );

    expect(screen.getByText('Something went wrong')).toBeInTheDocument();
    expect(screen.getByText(/We're sorry, but something unexpected happened/)).toBeInTheDocument();
    expect(screen.getByText('Refresh Page')).toBeInTheDocument();
  });

  it('provides reload functionality', () => {
    // Mock window.location.reload
    const mockReload = vi.fn();
    Object.defineProperty(window, 'location', {
      value: { reload: mockReload },
      writable: true,
    });

    render(
      <ErrorBoundary>
        <ThrowError shouldThrow={true} />
      </ErrorBoundary>
    );

    const reloadButton = screen.getByText('Refresh Page');
    reloadButton.click();

    expect(mockReload).toHaveBeenCalledOnce();
  });
});